<?xml version="1.0" encoding="utf-8"?>
<!-- This URDF was automatically created by SolidWorks to URDF Exporter! Originally created by Stephen Brawner (brawner@gmail.com) 
     Commit Version: 1.6.0-4-g7f85cfe  Build Version: 1.6.7995.38578
     For more information, please see http://wiki.ros.org/sw_urdf_exporter -->
<robot
  name="urdffp">
  <link
    name="base">
    <inertial>
      <origin
        xyz="0.00250555328330903 -3.81462588426087E-05 0.0316963277414826"
        rpy="0 0 0" />
      <mass
        value="0.272903164017977" />
      <inertia
        ixx="0.000429690662720169"
        ixy="-4.91905405591446E-07"
        ixz="5.0446404090374E-06"
        iyy="0.000444630381267082"
        iyz="-1.1942225610325E-07"
        izz="0.000690420746922854" />
    </inertial>
    <visual>
      <origin
        xyz="0 0 0"
        rpy="0 0 0" />
      <geometry>
        <mesh
          filename="package://urdffp/meshes/base.STL" />
      </geometry>
      <material
        name="">
        <color
          rgba="0.792156862745098 0.819607843137255 0.933333333333333 1" />
      </material>
    </visual>
    <collision>
      <origin
        xyz="0 0 0"
        rpy="0 0 0" />
      <geometry>
        <mesh
          filename="package://urdffp/meshes/base.STL" />
      </geometry>
    </collision>
  </link>
  <link
    name="piringan">
    <inertial>
      <origin
        xyz="7.1158142641946E-05 -0.0184666186242548 0.0329887975542059"
        rpy="0 0 0" />
      <mass
        value="0.0882364212464755" />
      <inertia
        ixx="5.52167146898469E-05"
        ixy="1.20492494645693E-08"
        ixz="-1.82420450568254E-08"
        iyy="6.33014176342086E-05"
        iyz="8.67867232448484E-06"
        izz="4.46058697242766E-05" />
    </inertial>
    <visual>
      <origin
        xyz="0 0 0"
        rpy="0 0 0" />
      <geometry>
        <mesh
          filename="package://urdffp/meshes/piringan.STL" />
      </geometry>
      <material
        name="">
        <color
          rgba="0.792156862745098 0.819607843137255 0.933333333333333 1" />
      </material>
    </visual>
    <collision>
      <origin
        xyz="0 0 0"
        rpy="0 0 0" />
      <geometry>
        <mesh
          filename="package://urdffp/meshes/piringan.STL" />
      </geometry>
    </collision>
  </link>
  <joint
    name="servopiringan"
    type="revolute">
    <origin
      xyz="-3.0958E-05 0 0.0689"
      rpy="0 0 0" />
    <parent
      link="base" />
    <child
      link="piringan" />
    <axis
      xyz="-0.0020906 0 -1" />
    <limit
      lower="-3.14"
      upper="3.14"
      effort="0.83357"
      velocity="5.236" />
  </joint>
  <link
    name="link1">
    <inertial>
      <origin
        xyz="0.0558755183846822 0.00100866111594956 0.00296163275902246"
        rpy="0 0 0" />
      <mass
        value="0.0802065215999488" />
      <inertia
        ixx="1.8336321239439E-05"
        ixy="-4.26590175619785E-07"
        ixz="-2.49033577033556E-07"
        iyy="0.000160165932423911"
        iyz="1.00241541645658E-07"
        izz="0.000174697138177849" />
    </inertial>
    <visual>
      <origin
        xyz="0 0 0"
        rpy="0 0 0" />
      <geometry>
        <mesh
          filename="package://urdffp/meshes/link1.STL" />
      </geometry>
      <material
        name="">
        <color
          rgba="0.792156862745098 0.819607843137255 0.933333333333333 1" />
      </material>
    </visual>
    <collision>
      <origin
        xyz="0 0 0"
        rpy="0 0 0" />
      <geometry>
        <mesh
          filename="package://urdffp/meshes/link1.STL" />
      </geometry>
    </collision>
  </link>
  <joint
    name="servolink1"
    type="revolute">
    <origin
      xyz="0.0001138 0 0.054433"
      rpy="-1.5708 -1.5708 0" />
    <parent
      link="piringan" />
    <child
      link="link1" />
    <axis
      xyz="0 0 -1" />
    <limit
      lower="-3.14"
      upper="3.14"
      effort="0.83357"
      velocity="5.236" />
  </joint>
  <link
    name="link2">
    <inertial>
      <origin
        xyz="0.0473240197953751 0.000304211858951464 -0.0268494662534417"
        rpy="0 0 0" />
      <mass
        value="0.12585545698654" />
      <inertia
        ixx="3.01850761095069E-05"
        ixy="-4.14096974678988E-07"
        ixz="-1.50995829214283E-12"
        iyy="9.45981727378192E-05"
        iyz="7.4107473724615E-14"
        izz="0.000102469638299712" />
    </inertial>
    <visual>
      <origin
        xyz="0 0 0"
        rpy="0 0 0" />
      <geometry>
        <mesh
          filename="package://urdffp/meshes/link2.STL" />
      </geometry>
      <material
        name="">
        <color
          rgba="0.792156862745098 0.819607843137255 0.933333333333333 1" />
      </material>
    </visual>
    <collision>
      <origin
        xyz="0 0 0"
        rpy="0 0 0" />
      <geometry>
        <mesh
          filename="package://urdffp/meshes/link2.STL" />
      </geometry>
    </collision>
  </link>
  <joint
    name="servolink2"
    type="revolute">
    <origin
      xyz="0.116 0.00030718 0"
      rpy="0 0 0" />
    <parent
      link="link1" />
    <child
      link="link2" />
    <axis
      xyz="0 0 -1" />
    <limit
      lower="-3.14"
      upper="3.14"
      effort="0.83357"
      velocity="5.236" />
  </joint>
  <link
    name="link3">
    <inertial>
      <origin
        xyz="0.0628215287302671 -0.0040623495513205 -0.0114412294838502"
        rpy="0 0 0" />
      <mass
        value="0.0260593092533598" />
      <inertia
        ixx="9.09683554106757E-06"
        ixy="-2.36209174504339E-07"
        ixz="-2.93645570162803E-08"
        iyy="1.53439259309833E-05"
        iyz="-1.46574704090451E-07"
        izz="1.61650308365597E-05" />
    </inertial>
    <visual>
      <origin
        xyz="0 0 0"
        rpy="0 0 0" />
      <geometry>
        <mesh
          filename="package://urdffp/meshes/link3.STL" />
      </geometry>
      <material
        name="">
        <color
          rgba="0.792156862745098 0.819607843137255 0.933333333333333 1" />
      </material>
    </visual>
    <collision>
      <origin
        xyz="0 0 0"
        rpy="0 0 0" />
      <geometry>
        <mesh
          filename="package://urdffp/meshes/link3.STL" />
      </geometry>
    </collision>
  </link>
  <joint
    name="servolink3"
    type="revolute">
    <origin
      xyz="0.094648 0.00060842 0"
      rpy="0 0 0" />
    <parent
      link="link2" />
    <child
      link="link3" />
    <axis
      xyz="0 0 1" />
    <limit
      lower="-3.14"
      upper="3.14"
      effort="0.83357"
      velocity="5.236" />
  </joint>
  <link
    name="linkgear1">
    <inertial>
      <origin
        xyz="0.0163906353388061 0.000516730054567798 0.00637440803941411"
        rpy="0 0 0" />
      <mass
        value="0.00474004808682916" />
      <inertia
        ixx="2.07881514044574E-07"
        ixy="4.02451023326036E-08"
        ixz="7.49281426603522E-08"
        iyy="2.70247207620343E-06"
        iyz="2.38664167546256E-09"
        izz="2.88535011788772E-06" />
    </inertial>
    <visual>
      <origin
        xyz="0 0 0"
        rpy="0 0 0" />
      <geometry>
        <mesh
          filename="package://urdffp/meshes/linkgear1.STL" />
      </geometry>
      <material
        name="">
        <color
          rgba="0.776470588235294 0.756862745098039 0.737254901960784 1" />
      </material>
    </visual>
    <collision>
      <origin
        xyz="0 0 0"
        rpy="0 0 0" />
      <geometry>
        <mesh
          filename="package://urdffp/meshes/linkgear1.STL" />
      </geometry>
    </collision>
  </link>
  <joint
    name="servogear"
    type="revolute">
    <origin
      xyz="0.08705 0.011 -0.0255"
      rpy="-1.5708 0 0" />
    <parent
      link="link3" />
    <child
      link="linkgear1" />
    <axis
      xyz="0 0 1" />
    <limit
      lower="-3.14"
      upper="3.14"
      effort="0.17652"
      velocity="10.472" />
  </joint>
  <link
    name="endpointgear">
    <inertial>
      <origin
        xyz="-0.317865599787913 0.000384707865205851 0.0330288180921796"
        rpy="0 0 0" />
      <mass
        value="0.605238076529163" />
      <inertia
        ixx="0.00178662577215017"
        ixy="-0.000338252148447424"
        ixz="0.00151227607641661"
        iyy="0.00655019527270797"
        iyz="0.000207474596412363"
        izz="0.00569264985514613" />
    </inertial>
    <visual>
      <origin
        xyz="0 0 0"
        rpy="0 0 0" />
      <geometry>
        <mesh
          filename="package://urdffp/meshes/endpointgear.STL" />
      </geometry>
      <material
        name="">
        <color
          rgba="1 1 1 1" />
      </material>
    </visual>
    <collision>
      <origin
        xyz="0 0 0"
        rpy="0 0 0" />
      <geometry>
        <mesh
          filename="package://urdffp/meshes/endpointgear.STL" />
      </geometry>
    </collision>
  </link>
  <joint
    name="endpoint1"
    type="fixed">
    <origin
      xyz="0.080522 -0.017346 0"
      rpy="0 0 0" />
    <parent
      link="linkgear1" />
    <child
      link="endpointgear" />
    <axis
      xyz="0 0 0" />
  </joint>
  <link
    name="linkgearpalsu">
    <inertial>
      <origin
        xyz="0.0090459102896332 -0.000332822380325673 0.00735793539836838"
        rpy="0 0 0" />
      <mass
        value="0.00723714741075858" />
      <inertia
        ixx="5.26278703132282E-07"
        ixy="2.71611746965217E-08"
        ixz="-8.13137293466571E-08"
        iyy="3.05691434567241E-06"
        iyz="2.99174191295334E-09"
        izz="3.5409337967525E-06" />
    </inertial>
    <visual>
      <origin
        xyz="0 0 0"
        rpy="0 0 0" />
      <geometry>
        <mesh
          filename="package://urdffp/meshes/linkgearpalsu.STL" />
      </geometry>
      <material
        name="">
        <color
          rgba="0.776470588235294 0.756862745098039 0.737254901960784 1" />
      </material>
    </visual>
    <collision>
      <origin
        xyz="0 0 0"
        rpy="0 0 0" />
      <geometry>
        <mesh
          filename="package://urdffp/meshes/linkgearpalsu.STL" />
      </geometry>
    </collision>
  </link>
  <joint
    name="servogearpalsu"
    type="revolute">
    <origin
      xyz="0.08695 0.011 0.0045"
      rpy="-1.5708 0 0" />
    <parent
      link="link3" />
    <child
      link="linkgearpalsu" />
    <axis
      xyz="0 0 1" />
    <limit
      lower="-3.14"
      upper="3.14"
      effort="0.17652"
      velocity="10.472" />
  </joint>
  <link
    name="endpointpalsu">
    <inertial>
      <origin
        xyz="-0.317271893020754 -0.00201862954833724 0.0330288180921796"
        rpy="0 0 0" />
      <mass
        value="0.605238076529163" />
      <inertia
        ixx="0.00178662577215017"
        ixy="-0.000338252148447424"
        ixz="0.00151227607641661"
        iyy="0.00655019527270797"
        iyz="0.000207474596412363"
        izz="0.00569264985514613" />
    </inertial>
    <visual>
      <origin
        xyz="0 0 0"
        rpy="0 0 0" />
      <geometry>
        <mesh
          filename="package://urdffp/meshes/endpointpalsu.STL" />
      </geometry>
      <material
        name="">
        <color
          rgba="1 1 1 1" />
      </material>
    </visual>
    <collision>
      <origin
        xyz="0 0 0"
        rpy="0 0 0" />
      <geometry>
        <mesh
          filename="package://urdffp/meshes/endpointpalsu.STL" />
      </geometry>
    </collision>
  </link>
  <joint
    name="endpoint2"
    type="fixed">
    <origin
      xyz="0.080028 0.015057 0"
      rpy="0 0 0" />
    <parent
      link="linkgearpalsu" />
    <child
      link="endpointpalsu" />
    <axis
      xyz="0 0 0" />
  </joint>
</robot>