<?xml version="1.0" encoding="utf-8"?>
<!-- This URDF was automatically created by SolidWorks to URDF Exporter! Originally created by Stephen Brawner (brawner@gmail.com) 
     Commit Version: 1.6.0-4-g7f85cfe  Build Version: 1.6.7995.38578
     For more information, please see http://wiki.ros.org/sw_urdf_exporter -->
<robot
  name="urdf_raditya">
  <link
    name="base">
    <inertial>
      <origin
        xyz="0.0043052 0.0028062 0.035641"
        rpy="0 0 0" />
      <mass
        value="0.11758" />
      <inertia
        ixx="0.00017835"
        ixy="-4.9135E-06"
        ixz="6.4979E-06"
        iyy="0.00015769"
        iyz="-9.5232E-07"
        izz="0.0002441" />
    </inertial>
    <visual>
      <origin
        xyz="0 0 0"
        rpy="0 0 0" />
      <geometry>
        <mesh
          filename="package://urdf_raditya/meshes/base.STL" />
      </geometry>
      <material
        name="">
        <color
          rgba="0.79216 0.81961 0.93333 1" />
      </material>
    </visual>
    <collision>
      <origin
        xyz="0 0 0"
        rpy="0 0 0" />
      <geometry>
        <mesh
          filename="package://urdf_raditya/meshes/base.STL" />
      </geometry>
    </collision>
  </link>
  <link
    name="piringanatas">
    <inertial>
      <origin
        xyz="0.00662326716442243 0.0146965458645561 -0.0109473531236563"
        rpy="0 0 0" />
      <mass
        value="0.0884033352804417" />
      <inertia
        ixx="4.55811245399596E-05"
        ixy="-2.09957703699821E-06"
        ixz="-1.02156058217576E-05"
        iyy="6.17587106704719E-05"
        iyz="-4.87159977570293E-06"
        izz="5.12104530088391E-05" />
    </inertial>
    <visual>
      <origin
        xyz="0 0 0"
        rpy="0 0 0" />
      <geometry>
        <mesh
          filename="package://urdf_raditya/meshes/piringanatas.STL" />
      </geometry>
      <material
        name="">
        <color
          rgba="0.792156862745098 0.819607843137255 0.933333333333333 1" />
      </material>
    </visual>
    <collision>
      <origin
        xyz="0 0 0"
        rpy="0 0 0" />
      <geometry>
        <mesh
          filename="package://urdf_raditya/meshes/piringanatas.STL" />
      </geometry>
    </collision>
  </link>
  <joint
    name="piringanatas"
    type="revolute">
    <origin
      xyz="0.011252 0 0.10942"
      rpy="0 0 0" />
    <parent
      link="base" />
    <child
      link="piringanatas" />
    <axis
      xyz="0.10229 0 0.99475" />
    <limit
      lower="0"
      upper="0"
      effort="2.5"
      velocity="5.76" />
  </joint>
  <link
    name="motor1">
    <inertial>
      <origin
        xyz="0.0349883501664646 0.0342885052966822 0.0052242919654968"
        rpy="0 0 0" />
      <mass
        value="0.0545469130635853" />
      <inertia
        ixx="2.80911055796775E-05"
        ixy="-2.130323205718E-05"
        ixz="2.16163102918942E-07"
        iyy="3.70841053280018E-05"
        iyz="-1.97313364931075E-07"
        izz="6.22148447294734E-05" />
    </inertial>
    <visual>
      <origin
        xyz="0 0 0"
        rpy="0 0 0" />
      <geometry>
        <mesh
          filename="package://urdf_raditya/meshes/motor1.STL" />
      </geometry>
      <material
        name="">
        <color
          rgba="0.792156862745098 0.819607843137255 0.933333333333333 1" />
      </material>
    </visual>
    <collision>
      <origin
        xyz="0 0 0"
        rpy="0 0 0" />
      <geometry>
        <mesh
          filename="package://urdf_raditya/meshes/motor1.STL" />
      </geometry>
    </collision>
  </link>
  <joint
    name="servomotor1"
    type="revolute">
    <origin
      xyz="0.0042247 0.002 -0.011804"
      rpy="1.5708 0 0" />
    <parent
      link="piringanatas" />
    <child
      link="motor1" />
    <axis
      xyz="0 0 1" />
    <limit
      lower="0"
      upper="0"
      effort="0.98067"
      velocity="5.236" />
  </joint>
  <link
    name="motor2">
    <inertial>
      <origin
        xyz="0.0352554172350953 -0.0315939483237078 -0.0194154666200635"
        rpy="0 0 0" />
      <mass
        value="0.109552734720318" />
      <inertia
        ixx="3.92889178697021E-05"
        ixy="2.2724246582332E-05"
        ixz="-5.50089290835613E-07"
        iyy="4.42825027669035E-05"
        iyz="4.92959485388425E-07"
        izz="6.80493347917691E-05" />
    </inertial>
    <visual>
      <origin
        xyz="0 0 0"
        rpy="0 0 0" />
      <geometry>
        <mesh
          filename="package://urdf_raditya/meshes/motor2.STL" />
      </geometry>
      <material
        name="">
        <color
          rgba="0.792156862745098 0.819607843137255 0.933333333333333 1" />
      </material>
    </visual>
    <collision>
      <origin
        xyz="0 0 0"
        rpy="0 0 0" />
      <geometry>
        <mesh
          filename="package://urdf_raditya/meshes/motor2.STL" />
      </geometry>
    </collision>
  </link>
  <joint
    name="servomotor2"
    type="revolute">
    <origin
      xyz="0.076652 0.06326 0.0015268"
      rpy="0 0 0" />
    <parent
      link="motor1" />
    <child
      link="motor2" />
    <axis
      xyz="0 0 1" />
    <limit
      lower="0"
      upper="0"
      effort="0.98067"
      velocity="5.235988" />
  </joint>
  <link
    name="motor3">
    <inertial>
      <origin
        xyz="0.0583304982650656 0.00604336651666494 -0.00131353241637874"
        rpy="0 0 0" />
      <mass
        value="0.027699365241157" />
      <inertia
        ixx="1.24797328388083E-05"
        ixy="8.87925120299493E-07"
        ixz="4.4734907042381E-07"
        iyy="1.39469631273968E-05"
        iyz="-1.09921993680852E-07"
        izz="1.46725992354734E-05" />
    </inertial>
    <visual>
      <origin
        xyz="0 0 0"
        rpy="0 0 0" />
      <geometry>
        <mesh
          filename="package://urdf_raditya/meshes/motor3.STL" />
      </geometry>
      <material
        name="">
        <color
          rgba="0.792156862745098 0.819607843137255 0.933333333333333 1" />
      </material>
    </visual>
    <collision>
      <origin
        xyz="0 0 0"
        rpy="0 0 0" />
      <geometry>
        <mesh
          filename="package://urdf_raditya/meshes/motor3.STL" />
      </geometry>
    </collision>
  </link>
  <joint
    name="servomotor3"
    type="revolute">
    <origin
      xyz="0.067697 -0.062662 0.00031939"
      rpy="0 0 0" />
    <parent
      link="motor2" />
    <child
      link="motor3" />
    <axis
      xyz="0 0 1" />
    <limit
      lower="0"
      upper="0"
      effort="0.98067"
      velocity="5.235988" />
  </joint>
  <link
    name="motor4_1">
    <inertial>
      <origin
        xyz="0.0035895 0.010018 0.0019105"
        rpy="0 0 0" />
      <mass
        value="0.0077585" />
      <inertia
        ixx="2.9119E-06"
        ixy="-9.2343E-07"
        ixz="2.7316E-10"
        iyy="1.0285E-06"
        iyz="2.1088E-09"
        izz="3.9017E-06" />
    </inertial>
    <visual>
      <origin
        xyz="0 0 0"
        rpy="0 0 0" />
      <geometry>
        <mesh
          filename="package://urdf_raditya/meshes/motor4_1.STL" />
      </geometry>
      <material
        name="">
        <color
          rgba="0.79216 0.81961 0.93333 1" />
      </material>
    </visual>
    <collision>
      <origin
        xyz="0 0 0"
        rpy="0 0 0" />
      <geometry>
        <mesh
          filename="package://urdf_raditya/meshes/motor4_1.STL" />
      </geometry>
    </collision>
  </link>
  <joint
    name="motor4_1"
    type="continuous">
    <origin
      xyz="0.079299 -0.012227 0.012654"
      rpy="1.5708 0 0" />
    <parent
      link="motor3" />
    <child
      link="motor4_1" />
    <axis
      xyz="0 0 1" />
    <limit
      effort="0.21575"
      velocity="10.472" />
  </joint>
  <!-- <link
    name="enpoint1">
    <inertial>
      <origin
        xyz="-0.21395 -0.077752 -0.011647"
        rpy="0 0 0" />
      <mass
        value="0" />
      <inertia
        ixx="0"
        ixy="0"
        ixz="0"
        iyy="0"
        iyz="0"
        izz="0" />
    </inertial>
    <visual>
      <origin
        xyz="0 0 0"
        rpy="0 0 0" />
      <geometry>
        <mesh
          filename="package://urdf_raditya/meshes/enpoint1.STL" />
      </geometry>
      <material
        name="">
        <color
          rgba="1 1 1 1" />
      </material>
    </visual>
    <collision>
      <origin
        xyz="0 0 0"
        rpy="0 0 0" />
      <geometry>
        <mesh
          filename="package://urdf_raditya/meshes/enpoint1.STL" />
      </geometry>
    </collision>
  </link>
  <joint
    name="enpoint1"
    type="prismatic">
    <origin
      xyz="0.043565 0.056218 0.0045594"
      rpy="0 0 0" />
    <parent
      link="motor4_1" />
    <child
      link="enpoint1" />
    <axis
      xyz="0 0 -1" />
    <limit
      lower="0"
      upper="0"
      effort="0"
      velocity="0" />
  </joint> -->
  <link
    name="motor4_2">
    <inertial>
      <origin
        xyz="0.00505708180058315 -0.0137191901792812 0.000268228191316597"
        rpy="0 0 0" />
      <mass
        value="0.00657272815903351" />
      <inertia
        ixx="2.3056169265561E-06"
        ixy="8.22797324331261E-07"
        ixz="3.97046694025453E-22"
        iyy="7.19004749886812E-07"
        iyz="-4.08006837141781E-22"
        izz="2.99148417197445E-06" />
    </inertial>
    <visual>
      <origin
        xyz="0 0 0"
        rpy="0 0 0" />
      <geometry>
        <mesh
          filename="package://urdf_raditya/meshes/motor4_2.STL" />
      </geometry>
      <material
        name="">
        <color
          rgba="0.792156862745098 0.819607843137255 0.933333333333333 1" />
      </material>
    </visual>
    <collision>
      <origin
        xyz="0 0 0"
        rpy="0 0 0" />
      <geometry>
        <mesh
          filename="package://urdf_raditya/meshes/motor4_2.STL" />
      </geometry>
    </collision>
  </link>
  <joint
    name="motor4_2"
    type="revolute">
    <origin
      xyz="0.079699 -0.012268 -0.020346"
      rpy="1.5708 0 0" />
    <parent
      link="motor3" />
    <child
      link="motor4_2" />
    <axis
      xyz="0 0 1" />
    <limit
      lower="0"
      upper="0"
      effort="0.21575"
      velocity="10.472" />
  </joint>
  <!-- <link
    name="enpoint2">
    <inertial>
      <origin
        xyz="-0.2113 0.068943 -0.010147"
        rpy="0 0 0" />
      <mass
        value="0" />
      <inertia
        ixx="0"
        ixy="0"
        ixz="0"
        iyy="0"
        iyz="0"
        izz="0" />
    </inertial>
    <visual>
      <origin
        xyz="0 0 0"
        rpy="0 0 0" />
      <geometry>
        <mesh
          filename="package://urdf_raditya/meshes/enpoint2.STL" />
      </geometry>
      <material
        name="">
        <color
          rgba="1 1 1 1" />
      </material>
    </visual>
    <collision>
      <origin
        xyz="0 0 0"
        rpy="0 0 0" />
      <geometry>
        <mesh
          filename="package://urdf_raditya/meshes/enpoint2.STL" />
      </geometry>
    </collision>
  </link>
  <joint
    name="enpoint2"
    type="fixed">
    <origin
      xyz="0.0405174702530282 -0.0574771522449544 0.00301822819131661"
      rpy="0 0 0" />
    <parent
      link="motor4_2" />
    <child
      link="enpoint2" />
    <axis
      xyz="0 0 0" />
  </joint> -->
</robot>